nohup: ignoring input
[2025-05-29 17:54:41] [INFO    ] discord.client: logging in using static token
[2025-05-29 17:54:43] [INFO    ] discord.gateway: Shard ID None has connected to Gateway (Session ID: 552cad01c84c5704b9f82e2728024f7c).
[2025-05-29 17:57:38] [WARNING ] discord.gateway: Shard ID None heartbeat blocked for more than 10 seconds.
Loop thread traceback (most recent call last):
  File "/media/myfiles/rintemo/discord_bot.py", line 60, in <module>
    client.run(DISCORD_TOKEN)
  File "/media/myfiles/rintemo/myenv/lib/python3.12/site-packages/discord/client.py", line 906, in run
    asyncio.run(runner())
  File "/usr/lib/python3.12/asyncio/runners.py", line 194, in run
    return runner.run(main)
  File "/usr/lib/python3.12/asyncio/runners.py", line 118, in run
    return self._loop.run_until_complete(task)
  File "/usr/lib/python3.12/asyncio/base_events.py", line 674, in run_until_complete
    self.run_forever()
  File "/usr/lib/python3.12/asyncio/base_events.py", line 641, in run_forever
    self._run_once()
  File "/usr/lib/python3.12/asyncio/base_events.py", line 1987, in _run_once
    handle._run()
  File "/usr/lib/python3.12/asyncio/events.py", line 88, in _run
    self._context.run(self._callback, *self._args)
  File "/media/myfiles/rintemo/myenv/lib/python3.12/site-packages/discord/client.py", line 481, in _run_event
    await coro(*args, **kwargs)
  File "/media/myfiles/rintemo/discord_bot.py", line 45, in on_message
    response = requests.post(FLASK_BACKEND_URL, data={
  File "/media/myfiles/rintemo/myenv/lib/python3.12/site-packages/requests/api.py", line 115, in post
    return request("post", url, data=data, json=json, **kwargs)
  File "/media/myfiles/rintemo/myenv/lib/python3.12/site-packages/requests/api.py", line 59, in request
    return session.request(method=method, url=url, **kwargs)
  File "/media/myfiles/rintemo/myenv/lib/python3.12/site-packages/requests/sessions.py", line 589, in request
    resp = self.send(prep, **send_kwargs)
  File "/media/myfiles/rintemo/myenv/lib/python3.12/site-packages/requests/sessions.py", line 703, in send
    r = adapter.send(request, **kwargs)
  File "/media/myfiles/rintemo/myenv/lib/python3.12/site-packages/requests/adapters.py", line 667, in send
    resp = conn.urlopen(
  File "/media/myfiles/rintemo/myenv/lib/python3.12/site-packages/urllib3/connectionpool.py", line 787, in urlopen
    response = self._make_request(
  File "/media/myfiles/rintemo/myenv/lib/python3.12/site-packages/urllib3/connectionpool.py", line 534, in _make_request
    response = conn.getresponse()
  File "/media/myfiles/rintemo/myenv/lib/python3.12/site-packages/urllib3/connection.py", line 516, in getresponse
    httplib_response = super().getresponse()
  File "/usr/lib/python3.12/http/client.py", line 1428, in getresponse
    response.begin()
  File "/usr/lib/python3.12/http/client.py", line 331, in begin
    version, status, reason = self._read_status()
  File "/usr/lib/python3.12/http/client.py", line 292, in _read_status
    line = str(self.fp.readline(_MAXLINE + 1), "iso-8859-1")
  File "/usr/lib/python3.12/socket.py", line 707, in readinto
    return self._sock.recv_into(b)

[2025-05-29 17:57:48] [WARNING ] discord.gateway: Shard ID None heartbeat blocked for more than 20 seconds.
Loop thread traceback (most recent call last):
  File "/media/myfiles/rintemo/discord_bot.py", line 60, in <module>
    client.run(DISCORD_TOKEN)
  File "/media/myfiles/rintemo/myenv/lib/python3.12/site-packages/discord/client.py", line 906, in run
    asyncio.run(runner())
  File "/usr/lib/python3.12/asyncio/runners.py", line 194, in run
    return runner.run(main)
  File "/usr/lib/python3.12/asyncio/runners.py", line 118, in run
    return self._loop.run_until_complete(task)
  File "/usr/lib/python3.12/asyncio/base_events.py", line 674, in run_until_complete
    self.run_forever()
  File "/usr/lib/python3.12/asyncio/base_events.py", line 641, in run_forever
    self._run_once()
  File "/usr/lib/python3.12/asyncio/base_events.py", line 1987, in _run_once
    handle._run()
  File "/usr/lib/python3.12/asyncio/events.py", line 88, in _run
    self._context.run(self._callback, *self._args)
  File "/media/myfiles/rintemo/myenv/lib/python3.12/site-packages/discord/client.py", line 481, in _run_event
    await coro(*args, **kwargs)
  File "/media/myfiles/rintemo/discord_bot.py", line 45, in on_message
    response = requests.post(FLASK_BACKEND_URL, data={
  File "/media/myfiles/rintemo/myenv/lib/python3.12/site-packages/requests/api.py", line 115, in post
    return request("post", url, data=data, json=json, **kwargs)
  File "/media/myfiles/rintemo/myenv/lib/python3.12/site-packages/requests/api.py", line 59, in request
    return session.request(method=method, url=url, **kwargs)
  File "/media/myfiles/rintemo/myenv/lib/python3.12/site-packages/requests/sessions.py", line 589, in request
    resp = self.send(prep, **send_kwargs)
  File "/media/myfiles/rintemo/myenv/lib/python3.12/site-packages/requests/sessions.py", line 703, in send
    r = adapter.send(request, **kwargs)
  File "/media/myfiles/rintemo/myenv/lib/python3.12/site-packages/requests/adapters.py", line 667, in send
    resp = conn.urlopen(
  File "/media/myfiles/rintemo/myenv/lib/python3.12/site-packages/urllib3/connectionpool.py", line 787, in urlopen
    response = self._make_request(
  File "/media/myfiles/rintemo/myenv/lib/python3.12/site-packages/urllib3/connectionpool.py", line 534, in _make_request
    response = conn.getresponse()
  File "/media/myfiles/rintemo/myenv/lib/python3.12/site-packages/urllib3/connection.py", line 516, in getresponse
    httplib_response = super().getresponse()
  File "/usr/lib/python3.12/http/client.py", line 1428, in getresponse
    response.begin()
  File "/usr/lib/python3.12/http/client.py", line 331, in begin
    version, status, reason = self._read_status()
  File "/usr/lib/python3.12/http/client.py", line 292, in _read_status
    line = str(self.fp.readline(_MAXLINE + 1), "iso-8859-1")
  File "/usr/lib/python3.12/socket.py", line 707, in readinto
    return self._sock.recv_into(b)

[2025-05-29 17:57:58] [WARNING ] discord.gateway: Shard ID None heartbeat blocked for more than 30 seconds.
Loop thread traceback (most recent call last):
  File "/media/myfiles/rintemo/discord_bot.py", line 60, in <module>
    client.run(DISCORD_TOKEN)
  File "/media/myfiles/rintemo/myenv/lib/python3.12/site-packages/discord/client.py", line 906, in run
    asyncio.run(runner())
  File "/usr/lib/python3.12/asyncio/runners.py", line 194, in run
    return runner.run(main)
  File "/usr/lib/python3.12/asyncio/runners.py", line 118, in run
    return self._loop.run_until_complete(task)
  File "/usr/lib/python3.12/asyncio/base_events.py", line 674, in run_until_complete
    self.run_forever()
  File "/usr/lib/python3.12/asyncio/base_events.py", line 641, in run_forever
    self._run_once()
  File "/usr/lib/python3.12/asyncio/base_events.py", line 1987, in _run_once
    handle._run()
  File "/usr/lib/python3.12/asyncio/events.py", line 88, in _run
    self._context.run(self._callback, *self._args)
  File "/media/myfiles/rintemo/myenv/lib/python3.12/site-packages/discord/client.py", line 481, in _run_event
    await coro(*args, **kwargs)
  File "/media/myfiles/rintemo/discord_bot.py", line 45, in on_message
    response = requests.post(FLASK_BACKEND_URL, data={
  File "/media/myfiles/rintemo/myenv/lib/python3.12/site-packages/requests/api.py", line 115, in post
    return request("post", url, data=data, json=json, **kwargs)
  File "/media/myfiles/rintemo/myenv/lib/python3.12/site-packages/requests/api.py", line 59, in request
    return session.request(method=method, url=url, **kwargs)
  File "/media/myfiles/rintemo/myenv/lib/python3.12/site-packages/requests/sessions.py", line 589, in request
    resp = self.send(prep, **send_kwargs)
  File "/media/myfiles/rintemo/myenv/lib/python3.12/site-packages/requests/sessions.py", line 703, in send
    r = adapter.send(request, **kwargs)
  File "/media/myfiles/rintemo/myenv/lib/python3.12/site-packages/requests/adapters.py", line 667, in send
    resp = conn.urlopen(
  File "/media/myfiles/rintemo/myenv/lib/python3.12/site-packages/urllib3/connectionpool.py", line 787, in urlopen
    response = self._make_request(
  File "/media/myfiles/rintemo/myenv/lib/python3.12/site-packages/urllib3/connectionpool.py", line 534, in _make_request
    response = conn.getresponse()
  File "/media/myfiles/rintemo/myenv/lib/python3.12/site-packages/urllib3/connection.py", line 516, in getresponse
    httplib_response = super().getresponse()
  File "/usr/lib/python3.12/http/client.py", line 1428, in getresponse
    response.begin()
  File "/usr/lib/python3.12/http/client.py", line 331, in begin
    version, status, reason = self._read_status()
  File "/usr/lib/python3.12/http/client.py", line 292, in _read_status
    line = str(self.fp.readline(_MAXLINE + 1), "iso-8859-1")
  File "/usr/lib/python3.12/socket.py", line 707, in readinto
    return self._sock.recv_into(b)

[2025-05-29 17:58:06] [ERROR   ] discord.client: Attempting a reconnect in 0.14s
Traceback (most recent call last):
  File "/media/myfiles/rintemo/myenv/lib/python3.12/site-packages/discord/client.py", line 704, in connect
    await self.ws.poll_event()
  File "/media/myfiles/rintemo/myenv/lib/python3.12/site-packages/discord/gateway.py", line 627, in poll_event
    await self.received_message(msg.data)
  File "/media/myfiles/rintemo/myenv/lib/python3.12/site-packages/discord/gateway.py", line 532, in received_message
    await self.send_as_json(beat)
  File "/media/myfiles/rintemo/myenv/lib/python3.12/site-packages/discord/gateway.py", line 663, in send_as_json
    await self.send(utils._to_json(data))
  File "/media/myfiles/rintemo/myenv/lib/python3.12/site-packages/discord/gateway.py", line 659, in send
    await self.socket.send_str(data)
  File "/media/myfiles/rintemo/myenv/lib/python3.12/site-packages/aiohttp/client_ws.py", line 245, in send_str
    await self._writer.send_frame(
  File "/media/myfiles/rintemo/myenv/lib/python3.12/site-packages/aiohttp/_websocket/writer.py", line 126, in send_frame
    raise ClientConnectionResetError("Cannot write to closing transport")
aiohttp.client_exceptions.ClientConnectionResetError: Cannot write to closing transport
[2025-05-29 17:58:09] [INFO    ] discord.gateway: Shard ID None has successfully RESUMED session 552cad01c84c5704b9f82e2728024f7c.
[2025-05-29 17:59:01] [WARNING ] discord.gateway: Shard ID None heartbeat blocked for more than 10 seconds.
Loop thread traceback (most recent call last):
  File "/media/myfiles/rintemo/discord_bot.py", line 60, in <module>
    client.run(DISCORD_TOKEN)
  File "/media/myfiles/rintemo/myenv/lib/python3.12/site-packages/discord/client.py", line 906, in run
    asyncio.run(runner())
  File "/usr/lib/python3.12/asyncio/runners.py", line 194, in run
    return runner.run(main)
  File "/usr/lib/python3.12/asyncio/runners.py", line 118, in run
    return self._loop.run_until_complete(task)
  File "/usr/lib/python3.12/asyncio/base_events.py", line 674, in run_until_complete
    self.run_forever()
  File "/usr/lib/python3.12/asyncio/base_events.py", line 641, in run_forever
    self._run_once()
  File "/usr/lib/python3.12/asyncio/base_events.py", line 1987, in _run_once
    handle._run()
  File "/usr/lib/python3.12/asyncio/events.py", line 88, in _run
    self._context.run(self._callback, *self._args)
  File "/media/myfiles/rintemo/myenv/lib/python3.12/site-packages/discord/client.py", line 481, in _run_event
    await coro(*args, **kwargs)
  File "/media/myfiles/rintemo/discord_bot.py", line 45, in on_message
    response = requests.post(FLASK_BACKEND_URL, data={
  File "/media/myfiles/rintemo/myenv/lib/python3.12/site-packages/requests/api.py", line 115, in post
    return request("post", url, data=data, json=json, **kwargs)
  File "/media/myfiles/rintemo/myenv/lib/python3.12/site-packages/requests/api.py", line 59, in request
    return session.request(method=method, url=url, **kwargs)
  File "/media/myfiles/rintemo/myenv/lib/python3.12/site-packages/requests/sessions.py", line 589, in request
    resp = self.send(prep, **send_kwargs)
  File "/media/myfiles/rintemo/myenv/lib/python3.12/site-packages/requests/sessions.py", line 703, in send
    r = adapter.send(request, **kwargs)
  File "/media/myfiles/rintemo/myenv/lib/python3.12/site-packages/requests/adapters.py", line 667, in send
    resp = conn.urlopen(
  File "/media/myfiles/rintemo/myenv/lib/python3.12/site-packages/urllib3/connectionpool.py", line 787, in urlopen
    response = self._make_request(
  File "/media/myfiles/rintemo/myenv/lib/python3.12/site-packages/urllib3/connectionpool.py", line 534, in _make_request
    response = conn.getresponse()
  File "/media/myfiles/rintemo/myenv/lib/python3.12/site-packages/urllib3/connection.py", line 516, in getresponse
    httplib_response = super().getresponse()
  File "/usr/lib/python3.12/http/client.py", line 1428, in getresponse
    response.begin()
  File "/usr/lib/python3.12/http/client.py", line 331, in begin
    version, status, reason = self._read_status()
  File "/usr/lib/python3.12/http/client.py", line 292, in _read_status
    line = str(self.fp.readline(_MAXLINE + 1), "iso-8859-1")
  File "/usr/lib/python3.12/socket.py", line 707, in readinto
    return self._sock.recv_into(b)

[2025-05-29 18:28:58] [WARNING ] discord.gateway: Shard ID None heartbeat blocked for more than 10 seconds.
Loop thread traceback (most recent call last):
  File "/media/myfiles/rintemo/discord_bot.py", line 60, in <module>
    client.run(DISCORD_TOKEN)
  File "/media/myfiles/rintemo/myenv/lib/python3.12/site-packages/discord/client.py", line 906, in run
    asyncio.run(runner())
  File "/usr/lib/python3.12/asyncio/runners.py", line 194, in run
    return runner.run(main)
  File "/usr/lib/python3.12/asyncio/runners.py", line 118, in run
    return self._loop.run_until_complete(task)
  File "/usr/lib/python3.12/asyncio/base_events.py", line 674, in run_until_complete
    self.run_forever()
  File "/usr/lib/python3.12/asyncio/base_events.py", line 641, in run_forever
    self._run_once()
  File "/usr/lib/python3.12/asyncio/base_events.py", line 1987, in _run_once
    handle._run()
  File "/usr/lib/python3.12/asyncio/events.py", line 88, in _run
    self._context.run(self._callback, *self._args)
  File "/media/myfiles/rintemo/myenv/lib/python3.12/site-packages/discord/client.py", line 481, in _run_event
    await coro(*args, **kwargs)
  File "/media/myfiles/rintemo/discord_bot.py", line 45, in on_message
    response = requests.post(FLASK_BACKEND_URL, data={
  File "/media/myfiles/rintemo/myenv/lib/python3.12/site-packages/requests/api.py", line 115, in post
    return request("post", url, data=data, json=json, **kwargs)
  File "/media/myfiles/rintemo/myenv/lib/python3.12/site-packages/requests/api.py", line 59, in request
    return session.request(method=method, url=url, **kwargs)
  File "/media/myfiles/rintemo/myenv/lib/python3.12/site-packages/requests/sessions.py", line 589, in request
    resp = self.send(prep, **send_kwargs)
  File "/media/myfiles/rintemo/myenv/lib/python3.12/site-packages/requests/sessions.py", line 703, in send
    r = adapter.send(request, **kwargs)
  File "/media/myfiles/rintemo/myenv/lib/python3.12/site-packages/requests/adapters.py", line 667, in send
    resp = conn.urlopen(
  File "/media/myfiles/rintemo/myenv/lib/python3.12/site-packages/urllib3/connectionpool.py", line 787, in urlopen
    response = self._make_request(
  File "/media/myfiles/rintemo/myenv/lib/python3.12/site-packages/urllib3/connectionpool.py", line 534, in _make_request
    response = conn.getresponse()
  File "/media/myfiles/rintemo/myenv/lib/python3.12/site-packages/urllib3/connection.py", line 516, in getresponse
    httplib_response = super().getresponse()
  File "/usr/lib/python3.12/http/client.py", line 1428, in getresponse
    response.begin()
  File "/usr/lib/python3.12/http/client.py", line 331, in begin
    version, status, reason = self._read_status()
  File "/usr/lib/python3.12/http/client.py", line 292, in _read_status
    line = str(self.fp.readline(_MAXLINE + 1), "iso-8859-1")
  File "/usr/lib/python3.12/socket.py", line 707, in readinto
    return self._sock.recv_into(b)

